Workbook
Name Excel_BuiltIn__FilterDatabase: '1 ESTADÍSTICA MENSUAL'!#REF!
Name Excel_BuiltIn__FilterDatabase: '2 RELAC. ING. Y EGR. '!$A$17:$N$27

Sheet LISTA
A1: 0
A2: 1
A3: 2
A4: 3
A5: 4
A6: 5
A7: 6
A8: 7
A9: 8
A10: 9
A11: 10
A12: 11
... A26: 25
A28: F
A29: M
A31: MATERNAL
A32: PREESCOLAR
A33: 1er GRADO
A34: 2do GRADO
A35: 3er GRADO
A36: 4to GRADO
A37: 5to GRADO
A38: 6to GRADO
A39: 1er AÑO
A40: 2do AÑO
... A102: NO

Sheet 1 ESTADÍSTICA MENSUAL
A1: REPÙBLICA BOLIVARIANA DE VENEZUELA
A2: MINISTERIO DEL PODER POPULAR PARA LA EDUCACIÓN
A3: GOBERNACIÓN DEL ESTADO MIRANDA
A4: ZONA EDUCATIVA DEL ESTADO BOLIVARIANO DE MIRANDA
A5: REGION EDUCATIVA ALTOS MIRANDINOS
A8: ESTADISTICA MENSUAL
A11: PLANTEL: | K11: CÓD. DE PLANTEL:
A12: AÑO ESCOLAR: | E12: MES: | K12: CÓD. ESTADISTICO:
J13: NRO DE DIAS HÁBILES:
A15: Cuadro 1 | C15: Matrícula Inicial del mes | F15: Ingresos en el mes | I15: Egresos en el mes | L15: Matrícula final del mes
A16: NIVEL | C16: Varones | D16: Hembras | E16: Total | F16: Varones | G16: Hembras | H16: Total | I16: Varones | J16: Hembras | K16: Total | L16: Varones | M16: Hembras | N16: Total
A17: INICIAL | E17: =SUM(C17:D17) -> 0 | F17: 0 | G17: 0 | H17: =SUM(F17:G17) -> 0 | I17: 0 | J17: 0 | K17: =SUM(I17:J17) -> 0 | L17: =C17+F17-I17 -> 0 | M17: =D17+G17-J17 -> 0 | N17: =SUM(L17:M17) -> 0
A18: PRIMARIA | E18: =SUM(C18:D18) -> 0 | F18: 0 | G18: 0 | H18: =SUM(F18:G18) -> 0 | I18: 0 | J18: 0 | K18: =SUM(I18:J18) -> 0 | L18: =C18+F18-I18 -> 0 | M18: =D18+G18-J18 -> 0 | N18: =SUM(L18:M18) -> 0
A19: MEDIA GRAL/TEC | E19: =SUM(C19:D19) -> 0 | F19: 0 | G19: 0 | H19: =SUM(F19:G19) -> 0 | I19: 0 | J19: 0 | K19: =SUM(I19:J19) -> 0 | L19: =C19+F19-I19 -> 0 | M19: =D19+G19-J19 -> 0 | N19: =SUM(L19:M19) -> 0
A20: TOTAL | C20: =SUM(C17:C19) -> 0 | D20: =SUM(D17:D19) -> 0 | E20: =SUM(E17:E19) -> 0 | F20: =SUM(F17:F19) -> 0 | G20: =SUM(G17:G19) -> 0 | H20: =SUM(H17:H19) -> 0 | I20: =SUM(I17:I19) -> 0 | J20: =SUM(J17:J19) -> 0 | ... N20: =SUM(N17:N19) -> 0
A21: Cuadro 2
A22: Nº | B22: Fecha | C22: Día | D22: NIVEL EDUCACIÓN INICIAL | G22: NIVEL EDUCACIÓN PRIMARIA | J22: NIVEL EDUC. MEDIA GRAL Y MEDIA TÉCNICA | M22: TOTAL ASISTENCIA
D23: Varones | E23: Hembras | F23: Total | G23: Varones | H23: Hembras | I23: Total | J23: Varones | K23: Hembras | L23: Total
A24: 1 | B24: 45446 | C24: Lunes | F24: =SUM(D24:E24) -> 0 | I24: =SUM(G24:H24) -> 0 | L24: =SUM(J24:K24) -> 0 | M24: =SUM(L24,I24,F24) -> 0
A25: 2 | B25: 45447 | C25: Martes | F25: =SUM(D25:E25) -> 0 | I25: =SUM(G25:H25) -> 0 | L25: =SUM(J25:K25) -> 0 | M25: =SUM(L25,I25,F25) -> 0
A26: 3 | B26: 45448 | C26: Miercoles | F26: =SUM(D26:E26) -> 0 | I26: =SUM(G26:H26) -> 0 | L26: =SUM(J26:K26) -> 0 | M26: =SUM(L26,I26,F26) -> 0
A27: 4 | B27: 45449 | C27: Jueves | F27: =SUM(D27:E27) -> 0 | I27: =SUM(G27:H27) -> 0 | L27: =SUM(J27:K27) -> 0 | M27: =SUM(L27,I27,F27) -> 0
A28: 5 | B28: 45450 | C28: Viernes | F28: =SUM(D28:E28) -> 0 | I28: =SUM(G28:H28) -> 0 | L28: =SUM(J28:K28) -> 0 | M28: =SUM(L28,I28,F28) -> 0
A29: 6 | B29: 45453 | C29: Lunes | F29: =SUM(D29:E29) -> 0 | I29: =SUM(G29:H29) -> 0 | L29: =SUM(J29:K29) -> 0 | M29: =SUM(L29,I29,F29) -> 0
A30: 7 | B30: 45454 | C30: Martes | F30: =SUM(D30:E30) -> 0 | I30: =SUM(G30:H30) -> 0 | L30: =SUM(J30:K30) -> 0 | M30: =SUM(L30,I30,F30) -> 0
A31: 8 | B31: 45455 | C31: Miercoles | F31: =SUM(D31:E31) -> 0 | I31: =SUM(G31:H31) -> 0 | L31: =SUM(J31:K31) -> 0 | M31: =SUM(L31,I31,F31) -> 0
A32: 9 | B32: 45456 | C32: Jueves | F32: =SUM(D32:E32) -> 0 | I32: =SUM(G32:H32) -> 0 | L32: =SUM(J32:K32) -> 0 | M32: =SUM(L32,I32,F32) -> 0
A33: 10 | B33: 45457 | C33: Viernes | F33: =SUM(D33:E33) -> 0 | I33: =SUM(G33:H33) -> 0 | L33: =SUM(J33:K33) -> 0 | M33: =SUM(L33,I33,F33) -> 0
A34: 11 | B34: 45460 | C34: Lunes | F34: =SUM(D34:E34) -> 0 | I34: =SUM(G34:H34) -> 0 | L34: =SUM(J34:K34) -> 0 | M34: =SUM(L34,I34,F34) -> 0
A35: 12 | B35: 45461 | C35: Martes | F35: =SUM(D35:E35) -> 0 | I35: =SUM(G35:H35) -> 0 | L35: =SUM(J35:K35) -> 0 | M35: =SUM(L35,I35,F35) -> 0
... A42: 19 | B42: 45471 | C42: Viernes | F42: =SUM(D42:E42) -> 0 | I42: =SUM(G42:H42) -> 0 | L42: =SUM(J42:K42) -> 0 | M42: =SUM(L42,I42,F42) -> 0
A43: 20 | F43: =SUM(D43:E43) -> 0 | I43: =SUM(G43:H43) -> 0 | L43: =SUM(J43:K43) -> 0 | M43: =SUM(L43,I43,F43) -> 0
A44: 21 | F44: =SUM(D44:E44) -> 0 | I44: =SUM(G44:H44) -> 0 | L44: =SUM(J44:K44) -> 0 | M44: =SUM(L44,I44,F44) -> 0
A45: 22 | F45: =SUM(D45:E45) -> 0 | I45: =SUM(G45:H45) -> 0 | L45: =SUM(J45:K45) -> 0 | M45: =SUM(L45,I45,F45) -> 0
A46: 23 | F46: =SUM(D46:E46) -> 0 | I46: =SUM(G46:H46) -> 0 | L46: =SUM(J46:K46) -> 0 | M46: =SUM(L46,I46,F46) -> 0
A47: TOTALES | D47: =SUM(D24:D46) -> 0 | E47: =SUM(E24:E46) -> 0 | F47: =SUM(F24:F46) -> 0 | G47: =SUM(G24:G46) -> 0 | H47: =SUM(H24:H46) -> 0 | I47: =SUM(I24:I46) -> 0 | J47: =SUM(J24:J46) -> 0 | K47: =SUM(K24:K46) -> 0 | ... M47: =SUM(M24:M46) -> 0
A48: Promedio Asist. | D48: =D47/M13 -> #DIV/0! | E48: =E47/M13 -> #DIV/0! | F48: =F47/M13 -> #DIV/0! | G48: =G47/M13 -> #DIV/0! | H48: =H47/M13 -> #DIV/0! | I48: =I47/M13 -> #DIV/0! | J48: =J47/M13 -> #DIV/0! | K48: =K47/M13 -> #DIV/0! | L48: =L47/M13 -> #DIV/0! | M48: =M47/M13 -> #DIV/0!
A49: Porcentaje Asist. | D49: =D48*100/L17 -> #DIV/0! | E49: =E48*100/M17 -> #DIV/0! | F49: =F48*100/N17 -> #DIV/0! | G49: =G48*100/L18 -> #DIV/0! | H49: =H48*100/M18 -> #DIV/0! | I49: =I48*100/N18 -> #DIV/0! | J49: =J48*100/L19 -> #DIV/0! | K49: =K48*100/M19 -> #DIV/0! | L49: =L48*100/N19 -> #DIV/0! | M49: =M48*100/N20 -> #DIV/0!
A51: Observaciones:
A59: Nombre Director(a): | J59: CARRIZAL,
...

Sheet 2 RELAC. ING. Y EGR. 
A1: REPÙBLICA BOLIVARIANA DE VENEZUELA
A2: MINISTERIO DEL PODER POPULAR PARA LA EDUCACIÓN
A3: GOBERNACIÓN DEL ESTADO MIRANDA
A4: ZONA EDUCATIVA DEL ESTADO BOLIVARIANO DE MIRANDA
A5: REGIÓN EDUCATIVA ALTOS MIRANDINOS
A8: RELACIÓN DE INGRESOS Y EGRESOS
A11: PLANTEL: | C11: ='1 ESTADÍSTICA MENSUAL'!C11 -> 0 | K11: CÓD. DE PLANTEL: | M11: ='1 ESTADÍSTICA MENSUAL'!M11 -> 0
A12: AÑO ESCOLAR: | C12: ='1 ESTADÍSTICA MENSUAL'!C12 -> 0 | E12: MES: | F12: ='1 ESTADÍSTICA MENSUAL'!F12 -> 0 | K12: CÓD. ESTADISTICO: | M12: ='1 ESTADÍSTICA MENSUAL'!M12 -> 0
K13: NRO DE DIAS HÁBILES: | M13: ='1 ESTADÍSTICA MENSUAL'!M13 -> 0
A15: RELACIÓN DE INGRESOS DURANTE EL MES:
B17: C. I. o C.E | C17: APELLIDOS Y NOMBRES | E17: LUG. DE NAC. | G17: FEC. NAC. | H17: EDAD | I17: SEXO | J17: ETAPA/GRADO/AÑO | K17: MOTIVO | N17: FECHA INGRESO
A18: 1
A19: 2
A20: 3
A21: 4
A22: 5
A23: 6
A24: 7
A25: 8
A26: 9
A27: 10
A29: RELACIÓN DE EGRESOS DURANTE EL MES:
B31: C. I. o C.E | C31: APELLIDOS Y NOMBRES | E31: LUG. DE NAC. | G31: FEC. NAC. | H31: EDAD | I31: SEXO | J31: ETAPA/GRADO/AÑO | K31: MOTIVO | N31: FECHA EGRESO
A32: 1
A33: 2
A34: 3
A35: 4
A36: 5
A37: 6
A38: 7
A39: 8
A40: 9
A41: 10
A46: ='1 ESTADÍSTICA MENSUAL'!A59:C59 -> Nombre Director(a): | D46: ='1 ESTADÍSTICA MENSUAL'!D59 -> 0 | J46: ='1 ESTADÍSTICA MENSUAL'!J59:K59 -> CARRIZAL, | L46: ='1 ESTADÍSTICA MENSUAL'!L59 -> 0
A47: ='1 ESTADÍSTICA MENSUAL'!A60:C60 -> Cédula de Identidad Nº: | D47: ='1 ESTADÍSTICA MENSUAL'!D60 -> 0 | J47: ='1 ESTADÍSTICA MENSUAL'!J60:K60 -> GUAICAIPURO, | L47: ='1 ESTADÍSTICA MENSUAL'!L60 -> 0
A48: ='1 ESTADÍSTICA MENSUAL'!A61:C61 -> Teléfono(s): | D48: ='1 ESTADÍSTICA MENSUAL'!D61 -> 0 | J48: ='1 ESTADÍSTICA MENSUAL'!J61:K61 -> LOS SALIAS, | L48: ='1 ESTADÍSTICA MENSUAL'!L61 -> 0
A49: ='1 ESTADÍSTICA MENSUAL'!A62:C62 -> Correo Electrónico: | D49: ='1 ESTADÍSTICA MENSUAL'!D62 -> 0

Sheet 3 ASIST. GRADO AÑO
A1: REPÙBLICA BOLIVARIANA DE VENEZUELA
A2: MINISTERIO DEL PODER POPULAR PARA LA EDUCACIÓN
A3: GOBERNACIÓN DEL ESTADO MIRANDA
A4: ZONA EDUCATIVA DEL ESTADO BOLIVARIANO DE MIRANDA
A5: REGIÓN EDUCATIVA ALTOS MIRANDINOS
A8: RELACIÓN DE DOCENTE, MATRÍCULA ATENDIDA Y PORCENTAJE DE ASISTENCIA
A11: PLANTEL: | C11: ='1 ESTADÍSTICA MENSUAL'!C11:G11 -> 0 | P11: CÓD. DE PLANTEL: | R11: ='1 ESTADÍSTICA MENSUAL'!M11 -> 0
A12: AÑO ESCOLAR: | C12: ='1 ESTADÍSTICA MENSUAL'!C12:D12 -> 0 | E12: MES | F12: ='1 ESTADÍSTICA MENSUAL'!F12:G12 -> 0 | P12: CÓD. ESTADISTICO: | R12: ='1 ESTADÍSTICA MENSUAL'!M12 -> 0
P13: NRO DE DIAS HÁBILES: | R13: ='1 ESTADÍSTICA MENSUAL'!M13 -> 0
A15: Nº | B15: Docente de Aula/Orientador | E15: C. I. | F15: Turno | G15: Dependencia | H15: Nivel/Grado/Año | I15: Sección | J15: Matrícula inicial del mes | M15: Matrícula final del mes | P15: Asistencia del mes | S15: Promedio de Asistencia | T15: % Asistencia
B16: Nombres y Apellidos | J16: V | K16: H | L16: T | M16: V | N16: H | O16: T | P16: V | Q16: H | R16: T
A17: 1 | L17: =SUM(J17:K17) -> 0 | O17: =SUM(M17:N17) -> 0 | R17: =SUM(P17:Q17) -> 0 | S17: =R17/R13 -> #DIV/0! | T17: =S17*100/O17 -> #DIV/0!
A18: 2 | L18: =SUM(J18:K18) -> 0 | O18: =SUM(M18:N18) -> 0 | R18: =SUM(P18:Q18) -> 0 | S18: =R18/R13 -> #DIV/0! | T18: =S18*100/O18 -> #DIV/0!
A19: 3 | L19: =SUM(J19:K19) -> 0 | O19: =SUM(M19:N19) -> 0 | R19: =SUM(P19:Q19) -> 0 | S19: =R19/R13 -> #DIV/0! | T19: =S19*100/O19 -> #DIV/0!
A20: 4 | L20: =SUM(J20:K20) -> 0 | O20: =SUM(M20:N20) -> 0 | R20: =SUM(P20:Q20) -> 0 | S20: =R20/R13 -> #DIV/0! | T20: =S20*100/O20 -> #DIV/0!
A21: 5 | L21: =SUM(J21:K21) -> 0 | O21: =SUM(M21:N21) -> 0 | R21: =SUM(P21:Q21) -> 0 | S21: =R21/R13 -> #DIV/0! | T21: =S21*100/O21 -> #DIV/0!
A22: 6 | L22: =SUM(J22:K22) -> 0 | O22: =SUM(M22:N22) -> 0 | R22: =SUM(P22:Q22) -> 0 | S22: =R22/R13 -> #DIV/0! | T22: =S22*100/O22 -> #DIV/0!
A23: 7 | L23: =SUM(J23:K23) -> 0 | O23: =SUM(M23:N23) -> 0 | R23: =SUM(P23:Q23) -> 0 | S23: =R23/R13 -> #DIV/0! | T23: =S23*100/O23 -> #DIV/0!
A24: 8 | L24: =SUM(J24:K24) -> 0 | O24: =SUM(M24:N24) -> 0 | R24: =SUM(P24:Q24) -> 0 | S24: =R24/R13 -> #DIV/0! | T24: =S24*100/O24 -> #DIV/0!
A25: 9 | L25: =SUM(J25:K25) -> 0 | O25: =SUM(M25:N25) -> 0 | R25: =SUM(P25:Q25) -> 0 | S25: =R25/R13 -> #DIV/0! | T25: =S25*100/O25 -> #DIV/0!
A26: 10 | L26: =SUM(J26:K26) -> 0 | O26: =SUM(M26:N26) -> 0 | R26: =SUM(P26:Q26) -> 0 | S26: =R26/R13 -> #DIV/0! | T26: =S26*100/O26 -> #DIV/0!
A27: 11 | L27: =SUM(J27:K27) -> 0 | O27: =SUM(M27:N27) -> 0 | R27: =SUM(P27:Q27) -> 0 | S27: =R27/R13 -> #DIV/0! | T27: =S27*100/O27 -> #DIV/0!
A28: 12 | L28: =SUM(J28:K28) -> 0 | O28: =SUM(M28:N28) -> 0 | R28: =SUM(P28:Q28) -> 0 | S28: =R28/R13 -> #DIV/0! | T28: =S28*100/O28 -> #DIV/0!
A29: 13 | L29: =SUM(J29:K29) -> 0 | O29: =SUM(M29:N29) -> 0 | R29: =SUM(P29:Q29) -> 0 | S29: =R29/R13 -> #DIV/0! | T29: =S29*100/O29 -> #DIV/0!
A30: 14 | L30: =SUM(J30:K30) -> 0 | O30: =SUM(M30:N30) -> 0 | R30: =SUM(P30:Q30) -> 0 | S30: =R30/R13 -> #DIV/0! | T30: =S30*100/O30 -> #DIV/0!
A31: 15 | L31: =SUM(J31:K31) -> 0 | O31: =SUM(M31:N31) -> 0 | R31: =SUM(P31:Q31) -> 0 | S31: =R31/R13 -> #DIV/0! | T31: =S31*100/O31 -> #DIV/0!
A32: 16 | L32: =SUM(J32:K32) -> 0 | O32: =SUM(M32:N32) -> 0 | R32: =SUM(P32:Q32) -> 0 | S32: =R32/R13 -> #DIV/0! | T32: =S32*100/O32 -> #DIV/0!
A33: 17 | L33: =SUM(J33:K33) -> 0 | O33: =SUM(M33:N33) -> 0 | R33: =SUM(P33:Q33) -> 0 | S33: =R33/R13 -> #DIV/0! | T33: =S33*100/O33 -> #DIV/0!
A34: 18 | L34: =SUM(J34:K34) -> 0 | O34: =SUM(M34:N34) -> 0 | R34: =SUM(P34:Q34) -> 0 | S34: =R34/R13 -> #DIV/0! | T34: =S34*100/O34 -> #DIV/0!
A35: 19 | L35: =SUM(J35:K35) -> 0 | O35: =SUM(M35:N35) -> 0 | R35: =SUM(P35:Q35) -> 0 | S35: =R35/R13 -> #DIV/0! | T35: =S35*100/O35 -> #DIV/0!
A36: 20 | L36: =SUM(J36:K36) -> 0 | O36: =SUM(M36:N36) -> 0 | R36: =SUM(P36:Q36) -> 0 | S36: =R36/R13 -> #DIV/0! | T36: =S36*100/O36 -> #DIV/0!
A37: 21 | L37: =SUM(J37:K37) -> 0 | O37: =SUM(M37:N37) -> 0 | R37: =SUM(P37:Q37) -> 0 | S37: =R37/R13 -> #DIV/0! | T37: =S37*100/O37 -> #DIV/0!
A38: 22 | L38: =SUM(J38:K38) -> 0 | O38: =SUM(M38:N38) -> 0 | R38: =SUM(P38:Q38) -> 0 | S38: =R38/R13 -> #DIV/0! | T38: =S38*100/O38 -> #DIV/0!
A39: 23 | L39: =SUM(J39:K39) -> 0 | O39: =SUM(M39:N39) -> 0 | R39: =SUM(P39:Q39) -> 0 | S39: =R39/R13 -> #DIV/0! | T39: =S39*100/O39 -> #DIV/0!
A40: 24 | L40: =SUM(J40:K40) -> 0 | O40: =SUM(M40:N40) -> 0 | R40: =SUM(P40:Q40) -> 0 | S40: =R40/R13 -> #DIV/0! | T40: =S40*100/O40 -> #DIV/0!
A41: 25 | L41: =SUM(J41:K41) -> 0 | O41: =SUM(M41:N41) -> 0 | R41: =SUM(P41:Q41) -> 0 | S41: =R41/R13 -> #DIV/0! | T41: =S41*100/O41 -> #DIV/0!
A42: 26 | L42: =SUM(J42:K42) -> 0 | O42: =SUM(M42:N42) -> 0 | R42: =SUM(P42:Q42) -> 0 | S42: =R42/R13 -> #DIV/0! | T42: =S42*100/O42 -> #DIV/0!
A43: 27 | L43: =SUM(J43:K43) -> 0 | O43: =SUM(M43:N43) -> 0 | R43: =SUM(P43:Q43) -> 0 | S43: =R43/R13 -> #DIV/0! | T43: =S43*100/O43 -> #DIV/0!
A44: 28 | L44: =SUM(J44:K44) -> 0 | O44: =SUM(M44:N44) -> 0 | R44: =SUM(P44:Q44) -> 0 | S44: =R44/R13 -> #DIV/0! | T44: =S44*100/O44 -> #DIV/0!
A45: 29 | L45: =SUM(J45:K45) -> 0 | O45: =SUM(M45:N45) -> 0 | R45: =SUM(P45:Q45) -> 0 | S45: =R45/R13 -> #DIV/0! | T45: =S45*100/O45 -> #DIV/0!
...

Sheet 4 ASIST PERS.
A1: REPÙBLICA BOLIVARIANA DE VENEZUELA
A2: MINISTERIO DEL PODER POPULAR PARA LA EDUCACIÓN
A3: GOBERNACIÓN DEL ESTADO MIRANDA
A4: ZONA EDUCATIVA DEL ESTADO BOLIVARIANO DE MIRANDA
A5: REGIÓN EDUCATIVA ALTOS MIRANDINOS
A8: RELACIÓN DE PERSONAL DOCENTE, ADMINISTRATIVO, OBRERO, Y PORCENTAJE DE ASISTENCIA
A11: PLANTEL: | C11: ='1 ESTADÍSTICA MENSUAL'!C11:G11 -> 0 | J11: CÓD. DE PLANTEL: | L11: ='1 ESTADÍSTICA MENSUAL'!M11 -> 0
A12: AÑO ESCOLAR: | C12: ='1 ESTADÍSTICA MENSUAL'!C12:D12 -> 0 | E12: MES | F12: ='1 ESTADÍSTICA MENSUAL'!F12:G12 -> 0 | J12: CÓD. ESTADISTICO: | L12: ='1 ESTADÍSTICA MENSUAL'!M12 -> 0
J13: NRO DE DIAS HÁBILES: | L13: ='1 ESTADÍSTICA MENSUAL'!M13 -> 0
A15: Nº | B15: Nombres y Apellidos | E15: C. I. | F15: Turno | G15: Tipo de Personal | H15: Asistencia | K15: Inasistencia | N15: Observaciones
H16: Días Hábiles | I16: Días Laborados | J16: % | K16: Días No laborados | L16: % | M16: Justificado
A17: 1 | H17: ='1 ESTADÍSTICA MENSUAL'!M13 -> 0 | J17: =I17*100/H17 -> #DIV/0! | K17: 0 | L17: =K17*100/H17 -> #DIV/0!
A18: 2 | H18: ='1 ESTADÍSTICA MENSUAL'!M13 -> 0 | J18: =I18*100/H18 -> #DIV/0! | K18: 0 | L18: =K18*100/H18 -> #DIV/0!
A19: 3 | H19: ='1 ESTADÍSTICA MENSUAL'!M13 -> 0 | J19: =I19*100/H19 -> #DIV/0! | K19: 0 | L19: =K19*100/H19 -> #DIV/0!
A20: 4 | H20: ='1 ESTADÍSTICA MENSUAL'!M13 -> 0 | J20: =I20*100/H20 -> #DIV/0! | K20: 0 | L20: =K20*100/H20 -> #DIV/0!
A21: 5 | H21: ='1 ESTADÍSTICA MENSUAL'!M13 -> 0 | J21: =I21*100/H21 -> #DIV/0! | K21: 0 | L21: =K21*100/H21 -> #DIV/0!
A22: 6 | H22: ='1 ESTADÍSTICA MENSUAL'!M13 -> 0 | J22: =I22*100/H22 -> #DIV/0! | K22: 4 | L22: =K22*100/H22 -> #DIV/0!
A23: 7 | H23: ='1 ESTADÍSTICA MENSUAL'!M13 -> 0 | J23: =I23*100/H23 -> #DIV/0! | K23: 0 | L23: =K23*100/H23 -> #DIV/0!
A24: 8 | H24: ='1 ESTADÍSTICA MENSUAL'!M13 -> 0 | J24: =I24*100/H24 -> #DIV/0! | K24: 0 | L24: =K24*100/H24 -> #DIV/0!
A25: 9 | H25: ='1 ESTADÍSTICA MENSUAL'!M13 -> 0 | J25: =I25*100/H25 -> #DIV/0! | K25: 0 | L25: =K25*100/H25 -> #DIV/0!
A26: 10 | H26: ='1 ESTADÍSTICA MENSUAL'!M13 -> 0 | J26: =I26*100/H26 -> #DIV/0! | K26: 0 | L26: =K26*100/H26 -> #DIV/0!
A27: 11 | H27: ='1 ESTADÍSTICA MENSUAL'!M13 -> 0 | J27: =I27*100/H27 -> #DIV/0! | K27: 0 | L27: =K27*100/H27 -> #DIV/0!
A28: 12 | H28: ='1 ESTADÍSTICA MENSUAL'!M13 -> 0 | J28: =I28*100/H28 -> #DIV/0! | K28: 0 | L28: =K28*100/H28 -> #DIV/0!
A29: 13 | H29: ='1 ESTADÍSTICA MENSUAL'!M13 -> 0 | J29: =I29*100/H29 -> #DIV/0! | K29: 0 | L29: =K29*100/H29 -> #DIV/0!
A30: 14 | H30: ='1 ESTADÍSTICA MENSUAL'!M13 -> 0 | J30: =I30*100/H30 -> #DIV/0! | K30: 0 | L30: =K30*100/H30 -> #DIV/0!
A31: 15 | H31: ='1 ESTADÍSTICA MENSUAL'!M13 -> 0 | J31: =I31*100/H31 -> #DIV/0! | K31: 0 | L31: =K31*100/H31 -> #DIV/0!
A32: 16 | H32: ='1 ESTADÍSTICA MENSUAL'!M13 -> 0 | J32: =I32*100/H32 -> #DIV/0! | K32: 3 | L32: =K32*100/H32 -> #DIV/0!
A33: 17 | H33: ='1 ESTADÍSTICA MENSUAL'!M13 -> 0 | J33: =I33*100/H33 -> #DIV/0! | K33: 0 | L33: =K33*100/H33 -> #DIV/0!
A34: 18 | H34: ='1 ESTADÍSTICA MENSUAL'!M13 -> 0 | J34: =I34*100/H34 -> #DIV/0! | K34: 0 | L34: =K34*100/H34 -> #DIV/0!
A35: 19 | H35: ='1 ESTADÍSTICA MENSUAL'!M13 -> 0 | J35: =I35*100/H35 -> #DIV/0! | K35: 4 | L35: =K35*100/H35 -> #DIV/0!
A36: 20 | H36: ='1 ESTADÍSTICA MENSUAL'!M13 -> 0 | J36: =I36*100/H36 -> #DIV/0! | K36: 0 | L36: =K36*100/H36 -> #DIV/0!
A37: 21 | H37: ='1 ESTADÍSTICA MENSUAL'!M13 -> 0 | J37: =I37*100/H37 -> #DIV/0! | K37: 0 | L37: =K37*100/H37 -> #DIV/0!
A38: 22 | H38: ='1 ESTADÍSTICA MENSUAL'!M13 -> 0 | J38: =I38*100/H38 -> #DIV/0! | K38: 19 | L38: =K38*100/H38 -> #DIV/0!
A39: 23 | H39: ='1 ESTADÍSTICA MENSUAL'!M13 -> 0 | J39: =I39*100/H39 -> #DIV/0! | K39: 4 | L39: =K39*100/H39 -> #DIV/0!
A40: 24 | H40: ='1 ESTADÍSTICA MENSUAL'!M13 -> 0 | J40: =I40*100/H40 -> #DIV/0! | K40: 1 | L40: =K40*100/H40 -> #DIV/0!
A41: 25 | H41: ='1 ESTADÍSTICA MENSUAL'!M13 -> 0 | J41: =I41*100/H41 -> #DIV/0! | K41: 0 | L41: =K41*100/H41 -> #DIV/0!
A42: 26 | H42: ='1 ESTADÍSTICA MENSUAL'!M13 -> 0 | J42: =I42*100/H42 -> #DIV/0! | K42: 19 | L42: =K42*100/H42 -> #DIV/0!
A43: 27 | H43: ='1 ESTADÍSTICA MENSUAL'!M13 -> 0 | J43: =I43*100/H43 -> #DIV/0! | K43: 0 | L43: =K43*100/H43 -> #DIV/0!
A44: 28 | H44: ='1 ESTADÍSTICA MENSUAL'!M13 -> 0 | J44: =I44*100/H44 -> #DIV/0! | K44: 0 | L44: =K44*100/H44 -> #DIV/0!
A45: 29 | H45: ='1 ESTADÍSTICA MENSUAL'!M13 -> 0 | J45: =I45*100/H45 -> #DIV/0! | K45: 1 | L45: =K45*100/H45 -> #DIV/0!
...

Sheet 4.1 ASIST PERS.
A1: REPÙBLICA BOLIVARIANA DE VENEZUELA
A2: MINISTERIO DEL PODER POPULAR PARA LA EDUCACIÓN
A3: GOBERNACIÓN DEL ESTADO MIRANDA
A4: ZONA EDUCATIVA DEL ESTADO BOLIVARIANO DE MIRANDA
A5: REGIÓN EDUCATIVA ALTOS MIRANDINOS
A8: RELACIÓN DE PERSONAL DOCENTE, ADMINISTRATIVO, OBRERO, Y PORCENTAJE DE ASISTENCIA
A11: PLANTEL: | C11: ='1 ESTADÍSTICA MENSUAL'!C11:G11 -> 0 | J11: CÓD. DE PLANTEL: | L11: ='1 ESTADÍSTICA MENSUAL'!M11 -> 0
A12: AÑO ESCOLAR: | C12: ='1 ESTADÍSTICA MENSUAL'!C12:D12 -> 0 | E12: MES | F12: ='1 ESTADÍSTICA MENSUAL'!F12:G12 -> 0 | J12: CÓD. ESTADISTICO: | L12: ='1 ESTADÍSTICA MENSUAL'!M12 -> 0
J13: NRO DE DIAS HÁBILES: | L13: ='1 ESTADÍSTICA MENSUAL'!M13 -> 0
A15: Nº | B15: Nombres y Apellidos | E15: C. I. | F15: Turno | G15: Tipo de Personal | H15: Asistencia | K15: Inasistencia | N15: Observaciones
H16: Días Hábiles | I16: Días Laborados | J16: % | K16: Días No laborados | L16: % | M16: Justificado
A17: 1 | H17: ='1 ESTADÍSTICA MENSUAL'!M13 -> 0 | J17: =I17*100/H17 -> #DIV/0! | L17: =K17*100/H17 -> #DIV/0!
A18: 2 | H18: ='1 ESTADÍSTICA MENSUAL'!M13 -> 0 | J18: =I18*100/H18 -> #DIV/0! | L18: =K18*100/H18 -> #DIV/0!
A19: 3 | H19: ='1 ESTADÍSTICA MENSUAL'!M13 -> 0 | J19: =I19*100/H19 -> #DIV/0! | L19: =K19*100/H19 -> #DIV/0!
A20: 4 | H20: ='1 ESTADÍSTICA MENSUAL'!M13 -> 0 | J20: =I20*100/H20 -> #DIV/0! | L20: =K20*100/H20 -> #DIV/0!
A21: 5 | H21: ='1 ESTADÍSTICA MENSUAL'!M13 -> 0 | J21: =I21*100/H21 -> #DIV/0! | L21: =K21*100/H21 -> #DIV/0!
A22: 6 | H22: ='1 ESTADÍSTICA MENSUAL'!M13 -> 0 | J22: =I22*100/H22 -> #DIV/0! | L22: =K22*100/H22 -> #DIV/0!
A23: 7 | H23: ='1 ESTADÍSTICA MENSUAL'!M13 -> 0 | J23: =I23*100/H23 -> #DIV/0! | L23: =K23*100/H23 -> #DIV/0!
A24: 8 | H24: ='1 ESTADÍSTICA MENSUAL'!M13 -> 0 | J24: =I24*100/H24 -> #DIV/0! | L24: =K24*100/H24 -> #DIV/0!
A25: 9 | H25: ='1 ESTADÍSTICA MENSUAL'!M13 -> 0 | J25: =I25*100/H25 -> #DIV/0! | L25: =K25*100/H25 -> #DIV/0!
A26: 10 | H26: ='1 ESTADÍSTICA MENSUAL'!M13 -> 0 | J26: =I26*100/H26 -> #DIV/0! | L26: =K26*100/H26 -> #DIV/0!
A27: 11 | H27: ='1 ESTADÍSTICA MENSUAL'!M13 -> 0 | J27: =I27*100/H27 -> #DIV/0! | L27: =K27*100/H27 -> #DIV/0!
A28: 12 | H28: ='1 ESTADÍSTICA MENSUAL'!M13 -> 0 | J28: =I28*100/H28 -> #DIV/0! | L28: =K28*100/H28 -> #DIV/0!
A29: 13 | H29: ='1 ESTADÍSTICA MENSUAL'!M13 -> 0 | J29: =I29*100/H29 -> #DIV/0! | L29: =K29*100/H29 -> #DIV/0!
A30: 14 | H30: ='1 ESTADÍSTICA MENSUAL'!M13 -> 0 | J30: =I30*100/H30 -> #DIV/0! | L30: =K30*100/H30 -> #DIV/0!
A31: 15 | H31: ='1 ESTADÍSTICA MENSUAL'!M13 -> 0 | J31: =I31*100/H31 -> #DIV/0! | L31: =K31*100/H31 -> #DIV/0!
A32: 16 | H32: ='1 ESTADÍSTICA MENSUAL'!M13 -> 0 | J32: =I32*100/H32 -> #DIV/0! | L32: =K32*100/H32 -> #DIV/0!
A33: 17 | H33: ='1 ESTADÍSTICA MENSUAL'!M13 -> 0 | J33: =I33*100/H33 -> #DIV/0! | L33: =K33*100/H33 -> #DIV/0!
A34: 18 | H34: ='1 ESTADÍSTICA MENSUAL'!M13 -> 0 | J34: =I34*100/H34 -> #DIV/0! | L34: =K34*100/H34 -> #DIV/0!
A35: 19 | H35: ='1 ESTADÍSTICA MENSUAL'!M13 -> 0 | J35: =I35*100/H35 -> #DIV/0! | L35: =K35*100/H35 -> #DIV/0!
A36: 20 | H36: ='1 ESTADÍSTICA MENSUAL'!M13 -> 0 | J36: =I36*100/H36 -> #DIV/0! | L36: =K36*100/H36 -> #DIV/0!
A37: 21 | H37: ='1 ESTADÍSTICA MENSUAL'!M13 -> 0 | J37: =I37*100/H37 -> #DIV/0! | L37: =K37*100/H37 -> #DIV/0!
A38: 22 | H38: ='1 ESTADÍSTICA MENSUAL'!M13 -> 0 | J38: =I38*100/H38 -> #DIV/0! | L38: =K38*100/H38 -> #DIV/0!
A39: 23 | H39: ='1 ESTADÍSTICA MENSUAL'!M13 -> 0 | J39: =I39*100/H39 -> #DIV/0! | L39: =K39*100/H39 -> #DIV/0!
A40: 24 | H40: ='1 ESTADÍSTICA MENSUAL'!M13 -> 0 | J40: =I40*100/H40 -> #DIV/0! | L40: =K40*100/H40 -> #DIV/0!
A41: 25 | H41: ='1 ESTADÍSTICA MENSUAL'!M13 -> 0 | J41: =I41*100/H41 -> #DIV/0! | L41: =K41*100/H41 -> #DIV/0!
A42: 26 | H42: ='1 ESTADÍSTICA MENSUAL'!M13 -> 0 | J42: =I42*100/H42 -> #DIV/0! | L42: =K42*100/H42 -> #DIV/0!
A43: 27 | H43: ='1 ESTADÍSTICA MENSUAL'!M13 -> 0 | J43: =I43*100/H43 -> #DIV/0! | L43: =K43*100/H43 -> #DIV/0!
A44: 28 | H44: ='1 ESTADÍSTICA MENSUAL'!M13 -> 0 | J44: =I44*100/H44 -> #DIV/0! | L44: =K44*100/H44 -> #DIV/0!
A45: 29 | H45: ='1 ESTADÍSTICA MENSUAL'!M13 -> 0 | J45: =I45*100/H45 -> #DIV/0! | L45: =K45*100/H45 -> #DIV/0!
...

Sheet 5 CLAS. EDAD Y SEXO
A1: REPÙBLICA BOLIVARIANA DE VENEZUELA
A2: MINISTERIO DEL PODER POPULAR PARA LA EDUCACIÓN
A3: GOBERNACIÓN DEL ESTADO MIRANDA
A4: ZONA EDUCATIVA DEL ESTADO BOLIVARIANO DE MIRANDA
A5: REGIÓN EDUCATIVA ALTOS MIRANDINOS
A7: CLASIFICACION DE ESTUDIANTES POR EDAD Y SEXO
A9: PLANTEL: | C9: ='1 ESTADÍSTICA MENSUAL'!C11 -> 0 | O9: CÓD. DE PLANTEL: | R9: ='1 ESTADÍSTICA MENSUAL'!M11 -> 0
A10: AÑO ESCOLAR: | C10: ='1 ESTADÍSTICA MENSUAL'!C12 -> 0 | E10: MES: | F10: ='1 ESTADÍSTICA MENSUAL'!F12 -> 0 | O10: CÓD. ESTADISTICO: | R10: ='1 ESTADÍSTICA MENSUAL'!M12 -> 0
O11: NRO DE DIAS HÁBILES: | R11: ='1 ESTADÍSTICA MENSUAL'!M13 -> 0
A13: EDUCACIÓN INICIAL | H13: TOTAL MATRÍCULA POR EDAD (AÑOS)
A14: N° DE SECCIONES | E14: SEXO | F14: NACIONALIDAD | H14: ETAPA MATERNAL | L14: ETAPA PREESCOLAR | Q14: TOTAL GENERAL
F15: V | G15: E | H15: MENOS DE 1 AÑO | I15: 1 AÑO | J15: 2 AÑOS | K15: TOTAL | L15: 3 AÑOS | M15: 4 AÑOS | N15: 5 AÑOS | O15: 6 AÑOS O MÁS | P15: TOTAL
A16: MATERNAL | C16: PREESCOLAR | E16: MAS | F16: 60 | G16: 0 | H16: 0 | I16: 0 | J16: 0 | K16: =SUM(H16:J16) -> 0 | L16: 9 | M16: 22 | N16: 17 | O16: 12 | P16: =SUM(L16:O16) -> 60 | Q16: =SUM(K16,P16) -> 60
A17: 0 | C17: 6 | E17: FEM | F17: 64 | G17: 0 | H17: 0 | I17: 0 | J17: 0 | K17: =SUM(H17:J17) -> 0 | L17: 11 | M17: 25 | N17: 20 | O17: 8 | P17: =SUM(L17:O17) -> 64 | Q17: =SUM(K17,P17) -> 64
A18: TOTAL | F18: =SUM(F16:F17) -> 124 | G18: =SUM(G16:G17) -> 0 | H18: =SUM(H16:H17) -> 0 | I18: =SUM(I16:I17) -> 0 | J18: =SUM(J16:J17) -> 0 | K18: =SUM(K16:K17) -> 0 | L18: =SUM(L16:L17) -> 20 | M18: =SUM(M16:M17) -> 47 | ... Q18: =SUM(Q16:Q17) -> 124
A20: EDUCACIÓN PRIMARIA
A21: GRADOS DE ESTUDIO | C21: N° DE SECCIONES | E21: SEXO | F21: NACIONALIDAD | H21: TOTAL MATRÍCULA POR EDAD (AÑOS)
F22: V | G22: E | H22: 5 | I22: 6 | J22: 7 | K22: 8 | L22: 9 | M22: 10 | N22: 11 | O22: 12 | P22: 13 | Q22: 14 | R22: 15 | S22: TOTAL
A23: PRIMERO | C23: 2 | E23: MAS | F23: 28 | I23: 17 | J23: 11 | S23: =SUM(H23:R23) -> 28
E24: FEM | F24: 25 | I24: 14 | J24: 11 | S24: =SUM(H24:R24) -> 25
A25: SEGUNDO | C25: 2 | E25: MAS | F25: 30 | J25: 21 | K25: 8 | L25: 1 | S25: =SUM(H25:R25) -> 30
E26: FEM | F26: 32 | J26: 18 | K26: 14 | S26: =SUM(H26:R26) -> 32
A27: TERCERO | C27: 2 | E27: MAS | F27: 23 | K27: 10 | L27: 12 | M27: 1 | S27: =SUM(H27:R27) -> 23
E28: FEM | F28: 27 | K28: 10 | L28: 12 | M28: 5 | S28: =SUM(H28:R28) -> 27
A29: CUARTO | C29: 2 | E29: MAS | F29: 31 | K29: 3 | L29: 20 | M29: 6 | N29: 1 | O29: 1 | S29: =SUM(H29:R29) -> 31
E30: FEM | F30: 26 | K30: 1 | L30: 15 | M30: 9 | N30: 1 | S30: =SUM(H30:R30) -> 26
A31: QUINTO | C31: 2 | E31: MAS | F31: 29 | M31: 11 | N31: 14 | O31: 3 | P31: 1 | S31: =SUM(H31:R31) -> 29
E32: FEM | F32: 32 | M32: 13 | N32: 16 | O32: 3 | S32: =SUM(H32:R32) -> 32
A33: SEXTO | C33: 2 | E33: MAS | F33: 26 | N33: 12 | O33: 12 | P33: 1 | Q33: 1 | S33: =SUM(H33:R33) -> 26
E34: FEM | F34: 30 | N34: 13 | O34: 15 | P34: 2 | S34: =SUM(H34:R34) -> 30
A35: SUBTOTAL | E35: MAS | F35: =SUM(F23,F25,F27,F29,F31,F33) -> 167 | G35: =SUM(G23,G25,G27,G29,G31,G33) -> 0 | H35: =SUM(H23,H25,H27,H29,H31,H33) -> 0 | I35: =SUM(I23,I25,I27,I29,I31,I33) -> 17 | J35: =SUM(J23,J25,J27,J29,J31,J33) -> 32 | K35: =SUM(K23,K25,K27,K29,K31,K33) -> 21 | L35: =SUM(L23,L25,L27,L29,L31,L33) -> 33 | M35: =SUM(M23,M25,M27,M29,M31,M33) -> 18 | ... S35: =SUM(S23,S25,S27,S29,S31,S33) -> 167
E36: FEM | F36: =SUM(F24,F26,F28,F30,F32,F34) -> 172 | G36: =SUM(G24,G26,G28,G30,G32,G34) -> 0 | H36: =SUM(H24,H26,H28,H30,H32,H34) -> 0 | I36: =SUM(I24,I26,I28,I30,I32,I34) -> 14 | J36: =SUM(J24,J26,J28,J30,J32,J34) -> 29 | K36: =SUM(K24,K26,K28,K30,K32,K34) -> 25 | L36: =SUM(L24,L26,L28,L30,L32,L34) -> 27 | M36: =SUM(M24,M26,M28,M30,M32,M34) -> 27 | ... S36: =SUM(S24,S26,S28,S30,S32,S34) -> 172
A37: TOTAL | F37: =SUM(F35:F36) -> 339 | G37: =SUM(G35:G36) -> 0 | H37: =SUM(H35:H36) -> 0 | I37: =SUM(I35:I36) -> 31 | J37: =SUM(J35:J36) -> 61 | K37: =SUM(K35:K36) -> 46 | L37: =SUM(L35:L36) -> 60 | M37: =SUM(M35:M36) -> 45 | ... S37: =SUM(S35:S36) -> 339
A39: EDUCACIÓN MEDIA GENERAL
A40: AÑOS DE ESTUDIO | C40: N° DE SECCIONES | E40: SEXO | F40: NACIONALIDAD | H40: TOTAL MATRÍCULA POR EDAD (AÑOS)
F41: V | G41: E | H41: 11 | I41: 12 | J41: 13 | K41: 14 | L41: 15 | M41: 16 | N41: 17 | O41: 18 | P41: 19 | Q41: 20 | R41: 21 o más | S41: TOTAL
A42: PRIMERO | C42: 5 | E42: MAS | F42: 73 | I42: 22 | J42: 38 | K42: 12 | L42: 1 | S42: =SUM(H42:R42) -> 73
E43: FEM | F43: 77 | I43: 36 | J43: 33 | K43: 5 | L43: 2 | M43: 1 | S43: =SUM(H43:R43) -> 77
A44: SEGUNDO | C44: 4 | E44: MAS | F44: 74 | J44: 31 | K44: 30 | L44: 7 | M44: 3 | N44: 2 | O44: 1 | S44: =SUM(H44:R44) -> 74
E45: FEM | F45: 58 | J45: 27 | K45: 27 | L45: 3 | M45: 1 | S45: =SUM(H45:R45) -> 58
...

Sheet 6 EST. EMB.
A1: REPÙBLICA BOLIVARIANA DE VENEZUELA
A2: MINISTERIO DEL PODER POPULAR PARA LA EDUCACIÓN
A3: GOBERNACIÓN DEL ESTADO MIRANDA
A4: ZONA EDUCATIVA DEL ESTADO BOLIVARIANO DE MIRANDA
A5: REGIÓN EDUCATIVA ALTOS MIRANDINOS
A8: ESTUDIANTES EMBARAZADAS
A10: PLANTEL: | C10: ='1 ESTADÍSTICA MENSUAL'!C11 -> 0 | K10: CÓD. DE PLANTEL: | N10: ='1 ESTADÍSTICA MENSUAL'!M11 -> 0
A11: AÑO ESCOLAR: | C11: ='1 ESTADÍSTICA MENSUAL'!C12 -> 0 | E11: MES: | F11: ='1 ESTADÍSTICA MENSUAL'!F12 -> 0 | K11: CÓD. ESTADISTICO: | N11: ='1 ESTADÍSTICA MENSUAL'!M12 -> 0
K12: NRO DE DIAS HÁBILES: | N12: ='1 ESTADÍSTICA MENSUAL'!M13 -> 0
A14: NÚMERO DE ESTUDIANTES EMBARAZADAS POR NIVEL EDUCATIVO Y EDAD
A15: NIVEL EDUCATIVO | D15: NÚMERO DE ESTUDIANTES EMBARAZADAS POR EDAD (AÑOS) | P15: TOTAL
D16: 10 | E16: 11 | F16: 12 | G16: 13 | H16: 14 | I16: 15 | J16: 16 | K16: 17 | L16: 18 | M16: 19 | N16: 20 O MÁS | O16: 21 O MÁS
A17: EDUCACIÓN PRIMARIA | D17: 0 | E17: 0 | F17: 0 | G17: 0 | H17: 0 | I17: 0 | J17: 0 | K17: 0 | L17: 0 | M17: 0 | N17: 0 | O17: 0 | P17: =SUM(D17:N17) -> 0
A18: EDUCACIÓN MEDIA GENERAL | D18: 0 | E18: 0 | F18: 0 | G18: 0 | H18: 0 | I18: 0 | J18: 1 | K18: 0 | L18: 0 | M18: 0 | N18: 0 | O18: 0 | P18: =SUM(D18:N18) -> 1
A19: EDUCACIÓN MEDIA TÉCNICA | D19: 0 | E19: 0 | F19: 0 | G19: 0 | H19: 0 | I19: 0 | J19: 0 | K19: 0 | L19: 0 | M19: 0 | N19: 0 | O19: 0 | P19: =SUM(D19:N19) -> 0
A20: TOTAL | D20: =SUM(D17:D19) -> 0 | E20: =SUM(E17:E19) -> 0 | F20: =SUM(F17:F19) -> 0 | G20: =SUM(G17:G19) -> 0 | H20: =SUM(H17:H19) -> 0 | I20: =SUM(I17:I19) -> 0 | J20: =SUM(J17:J19) -> 1 | K20: =SUM(K17:K19) -> 0 | ... P20: =SUM(P17:P19) -> 1
A23: ='1 ESTADÍSTICA MENSUAL'!A59:C59 -> Nombre Director(a): | D23: ='1 ESTADÍSTICA MENSUAL'!D59 -> 0 | K23: ='1 ESTADÍSTICA MENSUAL'!J59 -> CARRIZAL, | M23: ='1 ESTADÍSTICA MENSUAL'!L59 -> 0
A24: ='1 ESTADÍSTICA MENSUAL'!A60:C60 -> Cédula de Identidad Nº: | D24: ='1 ESTADÍSTICA MENSUAL'!D60 -> 0 | K24: ='1 ESTADÍSTICA MENSUAL'!J60 -> GUAICAIPURO, | M24: ='1 ESTADÍSTICA MENSUAL'!L60 -> 0
A25: ='1 ESTADÍSTICA MENSUAL'!A61:C61 -> Teléfono(s): | D25: ='1 ESTADÍSTICA MENSUAL'!D61 -> 0 | K25: ='1 ESTADÍSTICA MENSUAL'!J61 -> LOS SALIAS, | M25: ='1 ESTADÍSTICA MENSUAL'!L61 -> 0
A26: ='1 ESTADÍSTICA MENSUAL'!A62:C62 -> Correo Electrónico: | D26: ='1 ESTADÍSTICA MENSUAL'!D62 -> 0

Sheet 7 EST. EX.
A1: REPÙBLICA BOLIVARIANA DE VENEZUELA
A2: MINISTERIO DEL PODER POPULAR PARA LA EDUCACIÓN
A3: GOBERNACIÓN DEL ESTADO MIRANDA
A4: ZONA EDUCATIVA DEL ESTADO BOLIVARIANO DE MIRANDA
A5: REGIÓN EDUCATIVA ALTOS MIRANDINOS
A8: ESTUDIANTES EXTRANJEROS
A10: PLANTEL: | C10: ='1 ESTADÍSTICA MENSUAL'!C11 -> 0 | Z10: CÓD. DE PLANTEL: | AC10: ='1 ESTADÍSTICA MENSUAL'!M11 -> 0
A11: AÑO ESCOLAR: | C11: ='1 ESTADÍSTICA MENSUAL'!C12 -> 0 | E11: MES: | F11: ='1 ESTADÍSTICA MENSUAL'!F12 -> 0 | Z11: CÓD. ESTADISTICO: | AC11: ='1 ESTADÍSTICA MENSUAL'!M12 -> 0
Z12: NRO DE DIAS HÁBILES: | AC12: ='1 ESTADÍSTICA MENSUAL'!M13 -> 0
A14: NÚMERO DE ESTUDIANTES EXTRANJEROS POR PAIS DE NACIMIENTO
A15: NIVEL EDUCATIVO | D15: TOTAL DE ESTUDIANTES POR NACIONALIDAD Y SEXO
D16: PAIS DE ORIGEN | AE16: TOTAL
D17: BOLIVIA | F17: TOTAL | G17: BRASIL | I17: TOTAL | J17: COLOMBIA | L17: TOTAL | M17: CUBA | O17: TOTAL | P17: ECUADOR | R17: TOTAL | S17: PERU | U17: TOTAL | V17: OTRO (ESPECIFIQUE)
X18: TOTAL | AA18: TOTAL | AD18: TOTAL
D19: M | E19: F | G19: M | H19: F | J19: M | K19: F | M19: M | N19: F | P19: M | Q19: F | S19: M | T19: F | V19: M | W19: F | Y19: M | Z19: F | AB19: M | AC19: F
A20: EDUCACIÓN INICIAL | F20: =SUM(D20:E20) -> 0 | I20: =SUM(G20:H20) -> 0 | L20: =SUM(J20:K20) -> 0 | O20: =SUM(M20:N20) -> 0 | R20: =SUM(P20:Q20) -> 0 | U20: =SUM(S20:T20) -> 0 | X20: =SUM(V20:W20) -> 0 | AA20: =SUM(Y20:Z20) -> 0 | AD20: =SUM(AB20:AC20) -> 0 | AE20: =SUM(AD20,AA20,X20,U20,R20,O20,L20,I20,F20) -> 0
A21: EDUCACIÓN PRIMARIA | F21: =SUM(D21:E21) -> 0 | I21: =SUM(G21:H21) -> 0 | L21: =SUM(J21:K21) -> 0 | O21: =SUM(M21:N21) -> 0 | R21: =SUM(P21:Q21) -> 0 | U21: =SUM(S21:T21) -> 0 | X21: =SUM(V21:W21) -> 0 | AA21: =SUM(Y21:Z21) -> 0 | AD21: =SUM(AB21:AC21) -> 0 | AE21: =SUM(AD21,AA21,X21,U21,R21,O21,L21,I21,F21) -> 0
A22: EDUCACIÓN MEDIA GENERAL | F22: =SUM(D22:E22) -> 0 | I22: =SUM(G22:H22) -> 0 | L22: =SUM(J22:K22) -> 0 | O22: =SUM(M22:N22) -> 0 | R22: =SUM(P22:Q22) -> 0 | U22: =SUM(S22:T22) -> 0 | X22: =SUM(V22:W22) -> 0 | AA22: =SUM(Y22:Z22) -> 0 | AD22: =SUM(AB22:AC22) -> 0 | AE22: =SUM(AD22,AA22,X22,U22,R22,O22,L22,I22,F22) -> 0
A23: EDUCACIÓN MEDIA TÉCNICA | F23: =SUM(D23:E23) -> 0 | I23: =SUM(G23:H23) -> 0 | L23: =SUM(J23:K23) -> 0 | O23: =SUM(M23:N23) -> 0 | R23: =SUM(P23:Q23) -> 0 | U23: =SUM(S23:T23) -> 0 | X23: =SUM(V23:W23) -> 0 | AA23: =SUM(Y23:Z23) -> 0 | AD23: =SUM(AB23:AC23) -> 0 | AE23: =SUM(AD23,AA23,X23,U23,R23,O23,L23,I23,F23) -> 0
A24: TOTAL | D24: =SUM(D20:D23) -> 0 | E24: =SUM(E20:E23) -> 0 | F24: =SUM(F20:F23) -> 0 | G24: =SUM(G20:G23) -> 0 | H24: =SUM(H20:H23) -> 0 | I24: =SUM(I20:I23) -> 0 | J24: =SUM(J20:J23) -> 0 | K24: =SUM(K20:K23) -> 0 | ... AE24: =SUM(AE20:AE23) -> 0
A27: ='1 ESTADÍSTICA MENSUAL'!A59:C59 -> Nombre Director(a): | D27: ='1 ESTADÍSTICA MENSUAL'!D59 -> 0 | X27: ='1 ESTADÍSTICA MENSUAL'!J59 -> CARRIZAL, | AA27: ='1 ESTADÍSTICA MENSUAL'!L59 -> 0
A28: ='1 ESTADÍSTICA MENSUAL'!A60:C60 -> Cédula de Identidad Nº: | D28: ='1 ESTADÍSTICA MENSUAL'!D60 -> 0 | X28: ='1 ESTADÍSTICA MENSUAL'!J60 -> GUAICAIPURO, | AA28: ='1 ESTADÍSTICA MENSUAL'!L60 -> 0
A29: ='1 ESTADÍSTICA MENSUAL'!A61:C61 -> Teléfono(s): | D29: ='1 ESTADÍSTICA MENSUAL'!D61 -> 0 | X29: ='1 ESTADÍSTICA MENSUAL'!J61 -> LOS SALIAS, | AA29: ='1 ESTADÍSTICA MENSUAL'!L61 -> 0
A30: ='1 ESTADÍSTICA MENSUAL'!A62:C62 -> Correo Electrónico: | D30: ='1 ESTADÍSTICA MENSUAL'!D62 -> 0
